<?xml version="1.0" ?>
<!-- =================================================================================== -->
<!-- |    This document was autogenerated by xacro from tiangong2.0_complete_with_hands.xacro | -->
<!-- |    EDITING THIS FILE BY HAND IS NOT RECOMMENDED                                 | -->
<!-- =================================================================================== -->
<robot name="tiangong2pro-urdf_with_hands">
  <link name="pelvis">
    <inertial>
      <origin rpy="0 0 0" xyz="-0.000979 0.00068 -0.076922"/>
      <mass value="5.639"/>
      <inertia ixx="0.018304" ixy="-0.004328" ixz="6.1e-05" iyy="0.023292" iyz="6e-05" izz="0.024244"/>
    </inertial>
    <visual>
      <origin rpy="0 0 0" xyz="0 0 0"/>
      <geometry>
        <mesh filename="../meshes/pelvis.STL"/>
      </geometry>
      <material name="">
        <color rgba="0.752941176470588 0.752941176470588 0.752941176470588 1"/>
      </material>
    </visual>
    <collision>
      <origin rpy="0 0 0" xyz="0 0 0"/>
      <geometry>
        <mesh filename="../meshes/pelvis.STL"/>
      </geometry>
    </collision>
  </link>
  <link name="hip_roll_l_link">
    <inertial>
      <origin rpy="0 0 0" xyz="-0.001848 0.055849 -0.036017"/>
      <mass value="0.672983"/>
      <inertia ixx="0.00102" ixy="-7e-05" ixz="3.8e-05" iyy="0.003221" iyz="0.000281" izz="0.003272"/>
    </inertial>
    <visual>
      <origin rpy="0 0 0" xyz="0 0 0"/>
      <geometry>
        <mesh filename="../meshes/hip_roll_l_link.STL"/>
      </geometry>
      <material name="">
        <color rgba="0.752941176470588 0.752941176470588 0.752941176470588 1"/>
      </material>
    </visual>
    <collision>
      <origin rpy="0 0 0" xyz="0 0 0"/>
      <geometry>
        <mesh filename="../meshes/hip_roll_l_link.STL"/>
      </geometry>
    </collision>
  </link>
  <joint name="hip_roll_l_joint" type="revolute">
    <origin rpy="0 0 0" xyz="0 0.028 -0.0857"/>
    <parent link="pelvis"/>
    <child link="hip_roll_l_link"/>
    <axis xyz="1 0 0"/>
    <limit effort="235.0" lower="-0.7853981633974483" upper="0.7853981633974483" velocity="16.755160819145562"/>
  </joint>
  <link name="hip_pitch_l_link">
    <inertial>
      <origin rpy="0 0 0" xyz="0.001081 -8.8e-05 -0.013133"/>
      <mass value="3.951912"/>
      <inertia ixx="0.010841" ixy="-2.7e-05" ixz="0.000234" iyy="0.015597" iyz="0.000123" izz="0.00934"/>
    </inertial>
    <visual>
      <origin rpy="0 0 0" xyz="0 0 0"/>
      <geometry>
        <mesh filename="../meshes/hip_pitch_l_link.STL"/>
      </geometry>
      <material name="">
        <color rgba="0.752941176470588 0.752941176470588 0.752941176470588 1"/>
      </material>
    </visual>
    <collision>
      <origin rpy="0 0 0" xyz="0 0 0"/>
      <geometry>
        <mesh filename="../meshes/hip_pitch_l_link.STL"/>
      </geometry>
    </collision>
  </link>
  <joint name="hip_pitch_l_joint" type="revolute">
    <origin rpy="0 0 0" xyz="0 0.122 -0.046"/>
    <parent link="hip_roll_l_link"/>
    <child link="hip_pitch_l_link"/>
    <axis xyz="0 1 0"/>
    <limit effort="330.0" lower="-2.792526803190927" upper="2.0943951023931953" velocity="15.707963267948966"/>
  </joint>
  <link name="hip_yaw_l_link">
    <inertial>
      <origin rpy="0 0 0" xyz="0.004102 -0.006542 -0.121068"/>
      <mass value="6.670795"/>
      <inertia ixx="0.049573" ixy="-0.000228" ixz="-4.4e-05" iyy="0.053307" iyz="-0.001401" izz="0.017924"/>
    </inertial>
    <visual>
      <origin rpy="0 0 0" xyz="0 0 0"/>
      <geometry>
        <mesh filename="../meshes/hip_yaw_l_link.STL"/>
      </geometry>
      <material name="">
        <color rgba="0.752941176470588 0.752941176470588 0.752941176470588 1"/>
      </material>
    </visual>
    <collision>
      <origin rpy="0 0 0" xyz="0 0 0"/>
      <geometry>
        <mesh filename="../meshes/hip_yaw_l_link.STL"/>
      </geometry>
    </collision>
  </link>
  <joint name="hip_yaw_l_joint" type="revolute">
    <origin rpy="0 0 0" xyz="0 -0.00015 -0.0987"/>
    <parent link="hip_pitch_l_link"/>
    <child link="hip_yaw_l_link"/>
    <axis xyz="0 0 1"/>
    <limit effort="235.0" lower="-1.0471975511965976" upper="1.0471975511965976" velocity="16.755160819145562"/>
  </joint>
  <link name="knee_pitch_l_link">
    <inertial>
      <origin rpy="0 0 0" xyz="0.00018 0.001915 -0.178653"/>
      <mass value="2.312685"/>
      <inertia ixx="0.030244" ixy="-1e-05" ixz="-0.002398" iyy="0.03091" iyz="-0.000689" izz="0.002922"/>
    </inertial>
    <visual>
      <origin rpy="0 0 0" xyz="0 0 0"/>
      <geometry>
        <mesh filename="../meshes/knee_pitch_l_link.STL"/>
      </geometry>
      <material name="">
        <color rgba="0.752941176470588 0.752941176470588 0.752941176470588 1"/>
      </material>
    </visual>
    <collision>
      <origin rpy="0 0 0" xyz="0 0 0"/>
      <geometry>
        <mesh filename="../meshes/knee_pitch_l_link.STL"/>
      </geometry>
    </collision>
  </link>
  <joint name="knee_pitch_l_joint" type="revolute">
    <origin rpy="0 0 0" xyz="0 0.00010715 -0.3013"/>
    <parent link="hip_yaw_l_link"/>
    <child link="knee_pitch_l_link"/>
    <axis xyz="0 1 0"/>
    <limit effort="330.0" lower="0.0" upper="2.3911010752322315" velocity="15.707963267948966"/>
  </joint>
  <link name="ankle_pitch_l_link">
    <inertial>
      <origin rpy="0 0 0" xyz="0.0 0.0 0.0"/>
      <mass value="0.111609"/>
      <inertia ixx="1.8e-05" ixy="0.0" ixz="0.0" iyy="1.8e-05" iyz="0.0" izz="3.2e-05"/>
    </inertial>
    <visual>
      <origin rpy="0 0 0" xyz="0 0 0"/>
      <geometry>
        <mesh filename="../meshes/ankle_pitch_l_link.STL"/>
      </geometry>
      <material name="">
        <color rgba="0.752941176470588 0.752941176470588 0.752941176470588 1"/>
      </material>
    </visual>
    <collision>
      <origin rpy="0 0 0" xyz="0 0 0"/>
      <geometry>
        <mesh filename="../meshes/ankle_pitch_l_link.STL"/>
      </geometry>
    </collision>
  </link>
  <joint name="ankle_pitch_l_joint" type="revolute">
    <origin rpy="0 0 0" xyz="0 0 -0.4"/>
    <parent link="knee_pitch_l_link"/>
    <child link="ankle_pitch_l_link"/>
    <axis xyz="0 1 0"/>
    <limit effort="55.0" lower="-1.2217304763960306" upper="0.5235987755982988" velocity="14.137166941154069"/>
  </joint>
  <link name="ankle_roll_l_link">
    <inertial>
      <origin rpy="0 0 0" xyz="0.021235 0.0 -0.032883"/>
      <mass value="1.017381"/>
      <inertia ixx="0.001028" ixy="0.0" ixz="0.000622" iyy="0.006055" iyz="0.0" izz="0.00624"/>
    </inertial>
    <visual>
      <origin rpy="0 0 0" xyz="0 0 0"/>
      <geometry>
        <mesh filename="../meshes/ankle_roll_l_link.STL"/>
      </geometry>
      <material name="">
        <color rgba="0.752941176470588 0.752941176470588 0.752941176470588 1"/>
      </material>
    </visual>
    <collision>
      <origin rpy="0 0 0" xyz="0 0 0"/>
      <geometry>
        <mesh filename="../meshes/ankle_roll_l_link.STL"/>
      </geometry>
    </collision>
  </link>
  <joint name="ankle_roll_l_joint" type="revolute">
    <origin rpy="0 0 0" xyz="0 0 0"/>
    <parent link="ankle_pitch_l_link"/>
    <child link="ankle_roll_l_link"/>
    <axis xyz="1 0 0"/>
    <limit effort="55.0" lower="-0.5235987755982988" upper="0.5235987755982988" velocity="14.137166941154069"/>
  </joint>
  <link name="hip_roll_r_link">
    <inertial>
      <origin rpy="0 0 0" xyz="-0.001848 -0.055849 -0.036017"/>
      <mass value="0.672983"/>
      <inertia ixx="0.00102" ixy="7e-05" ixz="3.8e-05" iyy="0.003221" iyz="-0.000281" izz="0.003272"/>
    </inertial>
    <visual>
      <origin rpy="0 0 0" xyz="0 0 0"/>
      <geometry>
        <mesh filename="../meshes/hip_roll_r_link.STL"/>
      </geometry>
      <material name="">
        <color rgba="0.752941176470588 0.752941176470588 0.752941176470588 1"/>
      </material>
    </visual>
    <collision>
      <origin rpy="0 0 0" xyz="0 0 0"/>
      <geometry>
        <mesh filename="../meshes/hip_roll_r_link.STL"/>
      </geometry>
    </collision>
  </link>
  <joint name="hip_roll_r_joint" type="revolute">
    <origin rpy="0 0 0" xyz="0 -0.028 -0.0857"/>
    <parent link="pelvis"/>
    <child link="hip_roll_r_link"/>
    <axis xyz="1 0 0"/>
    <limit effort="235.0" lower="-0.7853981633974483" upper="0.7853981633974483" velocity="16.755160819145562"/>
  </joint>
  <link name="hip_pitch_r_link">
    <inertial>
      <origin rpy="0 0 0" xyz="0.001081 8.8e-05 -0.013133"/>
      <mass value="3.951912"/>
      <inertia ixx="0.010841" ixy="2.7e-05" ixz="0.000234" iyy="0.015597" iyz="-0.000123" izz="0.00934"/>
    </inertial>
    <visual>
      <origin rpy="0 0 0" xyz="0 0 0"/>
      <geometry>
        <mesh filename="../meshes/hip_pitch_r_link.STL"/>
      </geometry>
      <material name="">
        <color rgba="0.752941176470588 0.752941176470588 0.752941176470588 1"/>
      </material>
    </visual>
    <collision>
      <origin rpy="0 0 0" xyz="0 0 0"/>
      <geometry>
        <mesh filename="../meshes/hip_pitch_r_link.STL"/>
      </geometry>
    </collision>
  </link>
  <joint name="hip_pitch_r_joint" type="revolute">
    <origin rpy="0 0 0" xyz="0 -0.122 -0.046"/>
    <parent link="hip_roll_r_link"/>
    <child link="hip_pitch_r_link"/>
    <axis xyz="0 1 0"/>
    <limit effort="330.0" lower="-2.792526803190927" upper="2.0943951023931953" velocity="15.707963267948966"/>
  </joint>
  <link name="hip_yaw_r_link">
    <inertial>
      <origin rpy="0 0 0" xyz="0.004102 0.006542 -0.121068"/>
      <mass value="6.670795"/>
      <inertia ixx="0.049573" ixy="0.000228" ixz="-4.4e-05" iyy="0.053307" iyz="0.001401" izz="0.017924"/>
    </inertial>
    <visual>
      <origin rpy="0 0 0" xyz="0 0 0"/>
      <geometry>
        <mesh filename="../meshes/hip_yaw_r_link.STL"/>
      </geometry>
      <material name="">
        <color rgba="0.752941176470588 0.752941176470588 0.752941176470588 1"/>
      </material>
    </visual>
    <collision>
      <origin rpy="0 0 0" xyz="0 0 0"/>
      <geometry>
        <mesh filename="../meshes/hip_yaw_r_link.STL"/>
      </geometry>
    </collision>
  </link>
  <joint name="hip_yaw_r_joint" type="revolute">
    <origin rpy="0 0 0" xyz="0 0 -0.0987"/>
    <parent link="hip_pitch_r_link"/>
    <child link="hip_yaw_r_link"/>
    <axis xyz="0 0 1"/>
    <limit effort="235.0" lower="-1.0471975511965976" upper="1.0471975511965976" velocity="16.755160819145562"/>
  </joint>
  <link name="knee_pitch_r_link">
    <inertial>
      <origin rpy="0 0 0" xyz="0.00018 -0.001915 -0.178653"/>
      <mass value="2.312685"/>
      <inertia ixx="0.030244" ixy="1e-05" ixz="-0.002398" iyy="0.03091" iyz="0.000689" izz="0.002922"/>
    </inertial>
    <visual>
      <origin rpy="0 0 0" xyz="0 0 0"/>
      <geometry>
        <mesh filename="../meshes/knee_pitch_r_link.STL"/>
      </geometry>
      <material name="">
        <color rgba="0.752941176470588 0.752941176470588 0.752941176470588 1"/>
      </material>
    </visual>
    <collision>
      <origin rpy="0 0 0" xyz="0 0 0"/>
      <geometry>
        <mesh filename="../meshes/knee_pitch_r_link.STL"/>
      </geometry>
    </collision>
  </link>
  <joint name="knee_pitch_r_joint" type="revolute">
    <origin rpy="0 0 0" xyz="0 9.9938E-05 -0.3013"/>
    <parent link="hip_yaw_r_link"/>
    <child link="knee_pitch_r_link"/>
    <axis xyz="0 1 0"/>
    <limit effort="330.0" lower="0.0" upper="2.3911010752322315" velocity="15.707963267948966"/>
  </joint>
  <link name="ankle_pitch_r_link">
    <inertial>
      <origin rpy="0 0 0" xyz="0.0 0.0 0.0"/>
      <mass value="0.111609"/>
      <inertia ixx="1.8e-05" ixy="0.0" ixz="0.0" iyy="1.8e-05" iyz="0.0" izz="3.2e-05"/>
    </inertial>
    <visual>
      <origin rpy="0 0 0" xyz="0 0 0"/>
      <geometry>
        <mesh filename="../meshes/ankle_pitch_r_link.STL"/>
      </geometry>
      <material name="">
        <color rgba="0.752941176470588 0.752941176470588 0.752941176470588 1"/>
      </material>
    </visual>
    <collision>
      <origin rpy="0 0 0" xyz="0 0 0"/>
      <geometry>
        <mesh filename="../meshes/ankle_pitch_r_link.STL"/>
      </geometry>
    </collision>
  </link>
  <joint name="ankle_pitch_r_joint" type="revolute">
    <origin rpy="0 0 0" xyz="0 0.00099989 -0.4"/>
    <parent link="knee_pitch_r_link"/>
    <child link="ankle_pitch_r_link"/>
    <axis xyz="0 1 0"/>
    <limit effort="55.0" lower="-1.2217304763960306" upper="0.5235987755982988" velocity="14.137166941154069"/>
  </joint>
  <link name="ankle_roll_r_link">
    <inertial>
      <origin rpy="0 0 0" xyz="0.021235 0.0 -0.032883"/>
      <mass value="1.017381"/>
      <inertia ixx="0.001028" ixy="0.0" ixz="0.000622" iyy="0.006055" iyz="0.0" izz="0.00624"/>
    </inertial>
    <visual>
      <origin rpy="0 0 0" xyz="0 0 0"/>
      <geometry>
        <mesh filename="../meshes/ankle_roll_r_link.STL"/>
      </geometry>
      <material name="">
        <color rgba="0.752941176470588 0.752941176470588 0.752941176470588 1"/>
      </material>
    </visual>
    <collision>
      <origin rpy="0 0 0" xyz="0 0 0"/>
      <geometry>
        <mesh filename="../meshes/ankle_roll_r_link.STL"/>
      </geometry>
    </collision>
  </link>
  <joint name="ankle_roll_r_joint" type="revolute">
    <origin rpy="0 0 0" xyz="0 0 0"/>
    <parent link="ankle_pitch_r_link"/>
    <child link="ankle_roll_r_link"/>
    <axis xyz="1 0 0"/>
    <limit effort="55.0" lower="-0.5235987755982988" upper="0.5235987755982988" velocity="14.137166941154069"/>
  </joint>
  <link name="body_yaw_link">
    <inertial>
      <origin rpy="0 0 0" xyz="-0.000568 0.00056 0.231488"/>
      <mass value="22.0"/>
      <inertia ixx="0.429034" ixy="0.000293" ixz="-0.003462" iyy="0.379055" iyz="0.000237" izz="0.177142"/>
    </inertial>
    <visual>
      <origin rpy="0 0 0" xyz="0 0 0"/>
      <geometry>
        <mesh filename="../meshes/body_yaw_link.STL"/>
      </geometry>
      <material name="">
        <color rgba="0.752941176470588 0.752941176470588 0.752941176470588 1"/>
      </material>
    </visual>
    <collision>
      <origin rpy="0 0 0" xyz="0 0 0"/>
      <geometry>
        <mesh filename="../meshes/body_yaw_link.STL"/>
      </geometry>
    </collision>
  </link>
  <joint name="body_yaw_joint" type="revolute">
    <origin rpy="0 0 0" xyz="0 0 0"/>
    <parent link="pelvis"/>
    <child link="body_yaw_link"/>
    <axis xyz="0 0 1"/>
    <limit effort="91.0" lower="-2.9670597283903604" upper="3.141592653589793" velocity="9.215338450530059"/>
  </joint>
  <link name="head_yaw_link">
    <inertial>
      <origin rpy="0 0 0" xyz="-0.000202 0.000454 0.007248"/>
      <mass value="0.088397"/>
      <inertia ixx="9.5e-05" ixy="-1e-06" ixz="-3e-06" iyy="7.6e-05" iyz="-3e-06" izz="0.000106"/>
    </inertial>
    <visual>
      <origin rpy="0 0 0" xyz="0 0 0"/>
      <geometry>
        <mesh filename="../meshes/head_yaw_link.STL"/>
      </geometry>
      <material name="">
        <color rgba="0.752941176470588 0.752941176470588 0.752941176470588 1"/>
      </material>
    </visual>
    <collision>
      <origin rpy="0 0 0" xyz="0 0 0"/>
      <geometry>
        <mesh filename="../meshes/head_yaw_link.STL"/>
      </geometry>
    </collision>
  </link>
  <joint name="head_yaw_joint" type="revolute">
    <origin rpy="0 0 0" xyz="-0.002 0 0.56508"/>
    <parent link="body_yaw_link"/>
    <child link="head_yaw_link"/>
    <axis xyz="0 0 1"/>
    <limit effort="6.3" lower="-1.5707963267948966" upper="1.5707963267948966" velocity="7.5398223686155035"/>
  </joint>
  <link name="head_pitch_link">
    <inertial>
      <origin rpy="0 0 0" xyz="-0.000274 0.004118 2.3e-05"/>
      <mass value="0.23046"/>
      <inertia ixx="9.2e-05" ixy="1e-06" ixz="-1e-06" iyy="5.4e-05" iyz="0.0" izz="9.5e-05"/>
    </inertial>
    <visual>
      <origin rpy="0 0 0" xyz="0 0 0"/>
      <geometry>
        <mesh filename="../meshes/head_pitch_link.STL"/>
      </geometry>
      <material name="">
        <color rgba="0.752941176470588 0.752941176470588 0.752941176470588 1"/>
      </material>
    </visual>
    <collision>
      <origin rpy="0 0 0" xyz="0 0 0"/>
      <geometry>
        <mesh filename="../meshes/head_pitch_link.STL"/>
      </geometry>
    </collision>
  </link>
  <joint name="head_pitch_joint" type="revolute">
    <origin rpy="0 0.2618 0" xyz="0.01455 0 0.0304"/>
    <parent link="head_yaw_link"/>
    <child link="head_pitch_link"/>
    <axis xyz="0 1 0"/>
    <limit effort="6.3" lower="-0.4363323129985824" upper="0.4363323129985824" velocity="7.5398223686155035"/>
  </joint>
  <link name="head_roll_link">
    <inertial>
      <origin rpy="0 0 0" xyz="0.022467 0.001208 0.053952"/>
      <mass value="0.844627"/>
      <inertia ixx="0.00235" ixy="3.8e-05" ixz="0.000436" iyy="0.003365" iyz="6e-06" izz="0.002875"/>
    </inertial>
    <visual>
      <origin rpy="0 0 0" xyz="0 0 0"/>
      <geometry>
        <mesh filename="../meshes/head_roll_link.STL"/>
      </geometry>
      <material name="">
        <color rgba="0.752941176470588 0.752941176470588 0.752941176470588 1"/>
      </material>
    </visual>
    <collision>
      <origin rpy="0 0 0" xyz="0 0 0"/>
      <geometry>
        <mesh filename="../meshes/head_roll_link.STL"/>
      </geometry>
    </collision>
  </link>
  <joint name="head_roll_joint" type="revolute">
    <origin rpy="0 0 0" xyz="0 0 0"/>
    <parent link="head_pitch_link"/>
    <child link="head_roll_link"/>
    <axis xyz="1 0 0"/>
    <limit effort="6.3" lower="-0.4537856055185257" upper="0.4537856055185257" velocity="7.5398223686155035"/>
  </joint>
  <link name="camera_head_link">
    <inertial>
      <origin rpy="0 0 0" xyz="0.010986 -0.000307 -0.016475"/>
      <mass value="0.1"/>
      <inertia ixx="1.6e-05" ixy="0.0" ixz="0.0" iyy="8e-05" iyz="0.0" izz="7.7e-05"/>
    </inertial>
    <visual>
      <origin rpy="0 0 0" xyz="0 0 0"/>
      <geometry>
        <mesh filename="../meshes/camera_head_link.STL"/>
      </geometry>
      <material name="">
        <color rgba="0.752941176470588 0.752941176470588 0.752941176470588 1"/>
      </material>
    </visual>
    <collision>
      <origin rpy="0 0 0" xyz="0 0 0"/>
      <geometry>
        <mesh filename="../meshes/camera_head_link.STL"/>
      </geometry>
    </collision>
  </link>
  <joint name="camera_head_joint" type="fixed">
    <origin rpy="-1.8326 0 -1.5708" xyz="0.075191 0.010935 0.074436"/>
    <parent link="head_roll_link"/>
    <child link="camera_head_link"/>
    <axis xyz="0 0 0"/>
  </joint>
  <link name="shoulder_pitch_l_link">
    <inertial>
      <origin rpy="0 0 0" xyz="0.007494 0.064184 -2e-05"/>
      <mass value="1.032698"/>
      <inertia ixx="0.001025" ixy="-2.7e-05" ixz="-1e-06" iyy="0.001078" iyz="0.0" izz="0.001247"/>
    </inertial>
    <visual>
      <origin rpy="0 0 0" xyz="0 0 0"/>
      <geometry>
        <mesh filename="../meshes/shoulder_pitch_l_link.STL"/>
      </geometry>
      <material name="">
        <color rgba="0.752941176470588 0.752941176470588 0.752941176470588 1"/>
      </material>
    </visual>
    <collision>
      <origin rpy="0 0 0" xyz="0 0 0"/>
      <geometry>
        <mesh filename="../meshes/shoulder_pitch_l_link.STL"/>
      </geometry>
    </collision>
  </link>
  <joint name="shoulder_pitch_l_joint" type="revolute">
    <origin rpy="0.087266 0 0" xyz="0 0.1444 0.37712"/>
    <parent link="body_yaw_link"/>
    <child link="shoulder_pitch_l_link"/>
    <axis xyz="0 1 0"/>
    <limit effort="91.0" lower="-2.9670597283903604" upper="2.9670597283903604" velocity="9.215338450530059"/>
  </joint>
  <link name="shoulder_roll_l_link">
    <inertial>
      <origin rpy="0 0 0" xyz="0.002389 0.002259 -0.048236"/>
      <mass value="0.440997"/>
      <inertia ixx="0.001001" ixy="-4e-06" ixz="-2.5e-05" iyy="0.001313" iyz="-1.4e-05" izz="0.000911"/>
    </inertial>
    <visual>
      <origin rpy="0 0 0" xyz="0 0 0"/>
      <geometry>
        <mesh filename="../meshes/shoulder_roll_l_link.STL"/>
      </geometry>
      <material name="">
        <color rgba="0.752941176470588 0.752941176470588 0.752941176470588 1"/>
      </material>
    </visual>
    <collision>
      <origin rpy="0 0 0" xyz="0 0 0"/>
      <geometry>
        <mesh filename="../meshes/shoulder_roll_l_link.STL"/>
      </geometry>
    </collision>
  </link>
  <joint name="shoulder_roll_l_joint" type="revolute">
    <origin rpy="0 0 0" xyz="0 0.068 0"/>
    <parent link="shoulder_pitch_l_link"/>
    <child link="shoulder_roll_l_link"/>
    <axis xyz="1 0 0"/>
    <limit effort="95.0" lower="-1.0471975511965976" upper="1.8325957145940461" velocity="3.979350694547071"/>
  </joint>
  <link name="shoulder_yaw_l_link">
    <inertial>
      <origin rpy="0 0 0" xyz="0.008319 0.002686 -0.112525"/>
      <mass value="1.365033"/>
      <inertia ixx="0.009637" ixy="-5.7e-05" ixz="0.00095" iyy="0.0096" iyz="0.000339" izz="0.001331"/>
    </inertial>
    <visual>
      <origin rpy="0 0 0" xyz="0 0 0"/>
      <geometry>
        <mesh filename="../meshes/shoulder_yaw_l_link.STL"/>
      </geometry>
      <material name="">
        <color rgba="0.752941176470588 0.752941176470588 0.752941176470588 1"/>
      </material>
    </visual>
    <collision>
      <origin rpy="0 0 0" xyz="0 0 0"/>
      <geometry>
        <mesh filename="../meshes/shoulder_yaw_l_link.STL"/>
      </geometry>
    </collision>
  </link>
  <joint name="shoulder_yaw_l_joint" type="revolute">
    <origin rpy="0 0 0" xyz="0 0 -0.1025"/>
    <parent link="shoulder_roll_l_link"/>
    <child link="shoulder_yaw_l_link"/>
    <axis xyz="0 0 1"/>
    <limit effort="35.0" lower="-2.9670597283903604" upper="2.9670597283903604" velocity="5.235987755982989"/>
  </joint>
  <link name="elbow_pitch_l_link">
    <inertial>
      <origin rpy="0 0 0" xyz="-0.014694 -7.2e-05 -0.026081"/>
      <mass value="0.246311"/>
      <inertia ixx="0.000381" ixy="1e-06" ixz="-1.2e-05" iyy="0.000222" iyz="2e-06" izz="0.000401"/>
    </inertial>
    <visual>
      <origin rpy="0 0 0" xyz="0 0 0"/>
      <geometry>
        <mesh filename="../meshes/elbow_pitch_l_link.STL"/>
      </geometry>
      <material name="">
        <color rgba="0.752941176470588 0.752941176470588 0.752941176470588 1"/>
      </material>
    </visual>
    <collision>
      <origin rpy="0 0 0" xyz="0 0 0"/>
      <geometry>
        <mesh filename="../meshes/elbow_pitch_l_link.STL"/>
      </geometry>
    </collision>
  </link>
  <joint name="elbow_pitch_l_joint" type="revolute">
    <origin rpy="0 0 0" xyz="0.02 0 -0.1975"/>
    <parent link="shoulder_yaw_l_link"/>
    <child link="elbow_pitch_l_link"/>
    <axis xyz="0 1 0"/>
    <limit effort="35.0" lower="-2.6179938779914944" upper="0.2617993877991494" velocity="5.235987755982989"/>
  </joint>
  <link name="elbow_yaw_l_link">
    <inertial>
      <origin rpy="0 0 0" xyz="0.000158 0.001503 -0.069535"/>
      <mass value="0.986828"/>
      <inertia ixx="0.003108" ixy="-1e-06" ixz="8e-06" iyy="0.003035" iyz="8.9e-05" izz="0.00058"/>
    </inertial>
    <visual>
      <origin rpy="0 0 0" xyz="0 0 0"/>
      <geometry>
        <mesh filename="../meshes/elbow_yaw_l_link.STL"/>
      </geometry>
      <material name="">
        <color rgba="0.752941176470588 0.752941176470588 0.752941176470588 1"/>
      </material>
    </visual>
    <collision>
      <origin rpy="0 0 0" xyz="0 0 0"/>
      <geometry>
        <mesh filename="../meshes/elbow_yaw_l_link.STL"/>
      </geometry>
    </collision>
  </link>
  <joint name="elbow_yaw_l_joint" type="revolute">
    <origin rpy="0 0 0" xyz="-0.02 0 -0.0543"/>
    <parent link="elbow_pitch_l_link"/>
    <child link="elbow_yaw_l_link"/>
    <axis xyz="0 0 1"/>
    <limit effort="24.0" lower="-2.9670597283903604" upper="2.9670597283903604" velocity="10.471975511965978"/>
  </joint>
  <link name="wrist_pitch_l_link">
    <inertial>
      <origin rpy="0 0 0" xyz="0.005362 0.00064 -0.018812"/>
      <mass value="0.262007"/>
      <inertia ixx="7.1e-05" ixy="-3e-06" ixz="-2e-06" iyy="0.000112" iyz="-3e-06" izz="0.000111"/>
    </inertial>
    <visual>
      <origin rpy="0 0 0" xyz="0 0 0"/>
      <geometry>
        <mesh filename="../meshes/wrist_pitch_l_link.STL"/>
      </geometry>
      <material name="">
        <color rgba="0.752941176470588 0.752941176470588 0.752941176470588 1"/>
      </material>
    </visual>
    <collision>
      <origin rpy="0 0 0" xyz="0 0 0"/>
      <geometry>
        <mesh filename="../meshes/wrist_pitch_l_link.STL"/>
      </geometry>
    </collision>
  </link>
  <joint name="wrist_pitch_l_joint" type="revolute">
    <origin rpy="0 0 0" xyz="0 0 -0.1887"/>
    <parent link="elbow_yaw_l_link"/>
    <child link="wrist_pitch_l_link"/>
    <axis xyz="0 1 0"/>
    <limit effort="6.3" lower="-1.3089969389957472" upper="1.6580627893946132" velocity="7.5398223686155035"/>
  </joint>
  <link name="wrist_roll_l_link">
    <inertial>
      <origin rpy="0 0 0" xyz="0.000801 8.4e-05 -0.029302"/>
      <mass value="0.131751"/>
      <inertia ixx="6.9e-05" ixy="0.0" ixz="-1e-06" iyy="0.000116" iyz="0.0" izz="0.00011"/>
    </inertial>
    <visual>
      <origin rpy="0 0 0" xyz="0 0 0"/>
      <geometry>
        <mesh filename="../meshes/wrist_roll_l_link.STL"/>
      </geometry>
      <material name="">
        <color rgba="0.752941176470588 0.752941176470588 0.752941176470588 1"/>
      </material>
    </visual>
    <collision>
      <origin rpy="0 0 0" xyz="0 0 0"/>
      <geometry>
        <mesh filename="../meshes/wrist_roll_l_link.STL"/>
      </geometry>
    </collision>
  </link>
  <joint name="wrist_roll_l_joint" type="revolute">
    <origin rpy="0 0 0" xyz="0 0 -0.02"/>
    <parent link="wrist_pitch_l_link"/>
    <child link="wrist_roll_l_link"/>
    <axis xyz="1 0 0"/>
    <limit effort="6.3" lower="-1.0471975511965976" upper="0.7853981633974483" velocity="7.5398223686155035"/>
  </joint>
  <link name="left_tcp_link">
    <inertial>
      <origin rpy="0 0 0" xyz="0.000415 0.000651 0.017052"/>
      <mass value="0.218186"/>
      <inertia ixx="8.6e-05" ixy="-2e-06" ixz="-1e-06" iyy="8.4e-05" iyz="-1e-06" izz="0.000109"/>
    </inertial>
    <visual>
      <origin rpy="0 0 0" xyz="0 0 0"/>
      <geometry>
        <mesh filename="../meshes/left_tcp_link.STL"/>
      </geometry>
      <material name="">
        <color rgba="0.752941176470588 0.752941176470588 0.752941176470588 1"/>
      </material>
    </visual>
    <collision>
      <origin rpy="0 0 0" xyz="0 0 0"/>
      <geometry>
        <mesh filename="../meshes/left_tcp_link.STL"/>
      </geometry>
    </collision>
  </link>
  <joint name="left_tcp_joint" type="fixed">
    <origin rpy="0 0 -90" xyz="0 0 -0.0848"/>
    <parent link="wrist_roll_l_link"/>
    <child link="left_tcp_link"/>
    <axis xyz="0 0 0"/>
  </joint>
  <link name="shoulder_pitch_r_link">
    <inertial>
      <origin rpy="0 0 0" xyz="0.007494 -0.064184 -2e-05"/>
      <mass value="1.032698"/>
      <inertia ixx="0.001025" ixy="2.7e-05" ixz="-1e-06" iyy="0.001078" iyz="0.0" izz="0.001247"/>
    </inertial>
    <visual>
      <origin rpy="0 0 0" xyz="0 0 0"/>
      <geometry>
        <mesh filename="../meshes/shoulder_pitch_r_link.STL"/>
      </geometry>
      <material name="">
        <color rgba="0.752941176470588 0.752941176470588 0.752941176470588 1"/>
      </material>
    </visual>
    <collision>
      <origin rpy="0 0 0" xyz="0 0 0"/>
      <geometry>
        <mesh filename="../meshes/shoulder_pitch_r_link.STL"/>
      </geometry>
    </collision>
  </link>
  <joint name="shoulder_pitch_r_joint" type="revolute">
    <origin rpy="-0.087266 0 0" xyz="0 -0.1444 0.37712"/>
    <parent link="body_yaw_link"/>
    <child link="shoulder_pitch_r_link"/>
    <axis xyz="0 1 0"/>
    <limit effort="91.0" lower="-2.9670597283903604" upper="2.9670597283903604" velocity="9.215338450530059"/>
  </joint>
  <link name="shoulder_roll_r_link">
    <inertial>
      <origin rpy="0 0 0" xyz="0.002389 -0.002259 -0.048236"/>
      <mass value="0.440997"/>
      <inertia ixx="0.001001" ixy="4e-06" ixz="-2.5e-05" iyy="0.001313" iyz="1.4e-05" izz="0.000911"/>
    </inertial>
    <visual>
      <origin rpy="0 0 0" xyz="0 0 0"/>
      <geometry>
        <mesh filename="../meshes/shoulder_roll_r_link.STL"/>
      </geometry>
      <material name="">
        <color rgba="0.752941176470588 0.752941176470588 0.752941176470588 1"/>
      </material>
    </visual>
    <collision>
      <origin rpy="0 0 0" xyz="0 0 0"/>
      <geometry>
        <mesh filename="../meshes/shoulder_roll_r_link.STL"/>
      </geometry>
    </collision>
  </link>
  <joint name="shoulder_roll_r_joint" type="revolute">
    <origin rpy="0 0 0" xyz="0 -0.068 0"/>
    <parent link="shoulder_pitch_r_link"/>
    <child link="shoulder_roll_r_link"/>
    <axis xyz="1 0 0"/>
    <limit effort="95.0" lower="-1.8325957145940461" upper="1.0471975511965976" velocity="3.979350694547071"/>
  </joint>
  <link name="shoulder_yaw_r_link">
    <inertial>
      <origin rpy="0 0 0" xyz="0.008319 -0.002686 -0.112525"/>
      <mass value="1.365033"/>
      <inertia ixx="0.009637" ixy="5.7e-05" ixz="0.00095" iyy="0.0096" iyz="-0.000339" izz="0.001331"/>
    </inertial>
    <visual>
      <origin rpy="0 0 0" xyz="0 0 0"/>
      <geometry>
        <mesh filename="../meshes/shoulder_yaw_r_link.STL"/>
      </geometry>
      <material name="">
        <color rgba="0.752941176470588 0.752941176470588 0.752941176470588 1"/>
      </material>
    </visual>
    <collision>
      <origin rpy="0 0 0" xyz="0 0 0"/>
      <geometry>
        <mesh filename="../meshes/shoulder_yaw_r_link.STL"/>
      </geometry>
    </collision>
  </link>
  <joint name="shoulder_yaw_r_joint" type="revolute">
    <origin rpy="0 0 0" xyz="0 0 -0.1025"/>
    <parent link="shoulder_roll_r_link"/>
    <child link="shoulder_yaw_r_link"/>
    <axis xyz="0 0 1"/>
    <limit effort="35.0" lower="-2.9670597283903604" upper="2.9670597283903604" velocity="5.235987755982989"/>
  </joint>
  <link name="elbow_pitch_r_link">
    <inertial>
      <origin rpy="0 0 0" xyz="-0.014694 7.2e-05 -0.026081"/>
      <mass value="0.246311"/>
      <inertia ixx="0.000381" ixy="-1e-06" ixz="-1.2e-05" iyy="0.000222" iyz="-2e-06" izz="0.000401"/>
    </inertial>
    <visual>
      <origin rpy="0 0 0" xyz="0 0 0"/>
      <geometry>
        <mesh filename="../meshes/elbow_pitch_r_link.STL"/>
      </geometry>
      <material name="">
        <color rgba="0.752941176470588 0.752941176470588 0.752941176470588 1"/>
      </material>
    </visual>
    <collision>
      <origin rpy="0 0 0" xyz="0 0 0"/>
      <geometry>
        <mesh filename="../meshes/elbow_pitch_r_link.STL"/>
      </geometry>
    </collision>
  </link>
  <joint name="elbow_pitch_r_joint" type="revolute">
    <origin rpy="0 0 0" xyz="0.02 0 -0.1975"/>
    <parent link="shoulder_yaw_r_link"/>
    <child link="elbow_pitch_r_link"/>
    <axis xyz="0 1 0"/>
    <limit effort="35.0" lower="-2.6179938779914944" upper="0.2617993877991494" velocity="5.235987755982989"/>
  </joint>
  <link name="elbow_yaw_r_link">
    <inertial>
      <origin rpy="0 0 0" xyz="0.000158 -0.001503 -0.069535"/>
      <mass value="0.986828"/>
      <inertia ixx="0.003108" ixy="1e-06" ixz="8e-06" iyy="0.003035" iyz="-8.9e-05" izz="0.00058"/>
    </inertial>
    <visual>
      <origin rpy="0 0 0" xyz="0 0 0"/>
      <geometry>
        <mesh filename="../meshes/elbow_yaw_r_link.STL"/>
      </geometry>
      <material name="">
        <color rgba="0.752941176470588 0.752941176470588 0.752941176470588 1"/>
      </material>
    </visual>
    <collision>
      <origin rpy="0 0 0" xyz="0 0 0"/>
      <geometry>
        <mesh filename="../meshes/elbow_yaw_r_link.STL"/>
      </geometry>
    </collision>
  </link>
  <joint name="elbow_yaw_r_joint" type="revolute">
    <origin rpy="0 0 0" xyz="-0.02 0 -0.0543"/>
    <parent link="elbow_pitch_r_link"/>
    <child link="elbow_yaw_r_link"/>
    <axis xyz="0 0 1"/>
    <limit effort="24.0" lower="-2.9670597283903604" upper="2.9670597283903604" velocity="10.471975511965978"/>
  </joint>
  <link name="wrist_pitch_r_link">
    <inertial>
      <origin rpy="0 0 0" xyz="0.005362 -0.00064 -0.018812"/>
      <mass value="0.262007"/>
      <inertia ixx="7.1e-05" ixy="3e-06" ixz="-2e-06" iyy="0.000112" iyz="3e-06" izz="0.000111"/>
    </inertial>
    <visual>
      <origin rpy="0 0 0" xyz="0 0 0"/>
      <geometry>
        <mesh filename="../meshes/wrist_pitch_r_link.STL"/>
      </geometry>
      <material name="">
        <color rgba="0.752941176470588 0.752941176470588 0.752941176470588 1"/>
      </material>
    </visual>
    <collision>
      <origin rpy="0 0 0" xyz="0 0 0"/>
      <geometry>
        <mesh filename="../meshes/wrist_pitch_r_link.STL"/>
      </geometry>
    </collision>
  </link>
  <joint name="wrist_pitch_r_joint" type="revolute">
    <origin rpy="0 0 0" xyz="0 0 -0.1887"/>
    <parent link="elbow_yaw_r_link"/>
    <child link="wrist_pitch_r_link"/>
    <axis xyz="0 1 0"/>
    <limit effort="6.3" lower="-1.3089969389957472" upper="1.6580627893946132" velocity="7.5398223686155035"/>
  </joint>
  <link name="wrist_roll_r_link">
    <inertial>
      <origin rpy="0 0 0" xyz="0.000801 -8.4e-05 -0.029302"/>
      <mass value="0.131751"/>
      <inertia ixx="6.9e-05" ixy="0.0" ixz="-1e-06" iyy="0.000116" iyz="0.0" izz="0.00011"/>
    </inertial>
    <visual>
      <origin rpy="0 0 0" xyz="0 0 0"/>
      <geometry>
        <mesh filename="../meshes/wrist_roll_r_link.STL"/>
      </geometry>
      <material name="">
        <color rgba="0.752941176470588 0.752941176470588 0.752941176470588 1"/>
      </material>
    </visual>
    <collision>
      <origin rpy="0 0 0" xyz="0 0 0"/>
      <geometry>
        <mesh filename="../meshes/wrist_roll_r_link.STL"/>
      </geometry>
    </collision>
  </link>
  <joint name="wrist_roll_r_joint" type="revolute">
    <origin rpy="0 0 0" xyz="0 0 -0.02"/>
    <parent link="wrist_pitch_r_link"/>
    <child link="wrist_roll_r_link"/>
    <axis xyz="1 0 0"/>
    <limit effort="6.3" lower="-0.7853981633974483" upper="1.0471975511965976" velocity="7.5398223686155035"/>
  </joint>
  <link name="right_tcp_link">
    <inertial>
      <origin rpy="0 0 0" xyz="0.000415 -0.000651 0.017052"/>
      <mass value="0.218186"/>
      <inertia ixx="8.6e-05" ixy="2e-06" ixz="-1e-06" iyy="8.4e-05" iyz="1e-06" izz="0.000109"/>
    </inertial>
    <visual>
      <origin rpy="0 0 0" xyz="0 0 0"/>
      <geometry>
        <mesh filename="../meshes/right_tcp_link.STL"/>
      </geometry>
      <material name="">
        <color rgba="0.752941176470588 0.752941176470588 0.752941176470588 1"/>
      </material>
    </visual>
    <collision>
      <origin rpy="0 0 0" xyz="0 0 0"/>
      <geometry>
        <mesh filename="../meshes/right_tcp_link.STL"/>
      </geometry>
    </collision>
  </link>
  <joint name="right_tcp_joint" type="fixed">
    <origin rpy="0 0 90" xyz="0 0 -0.0848"/>
    <parent link="wrist_roll_r_link"/>
    <child link="right_tcp_link"/>
    <axis xyz="0 0 0"/>
  </joint>
  <link name="camera_body_front_link">
    <inertial>
      <origin rpy="0 0 0" xyz="0.023316 0.000241 -0.013373"/>
      <mass value="0.1"/>
      <inertia ixx="1.5e-05" ixy="1e-06" ixz="-1e-06" iyy="0.000127" iyz="0.0" izz="0.000127"/>
    </inertial>
    <visual>
      <origin rpy="0 0 0" xyz="0 0 0"/>
      <geometry>
        <mesh filename="../meshes/camera_body_front_link.STL"/>
      </geometry>
      <material name="">
        <color rgba="0.752941176470588 0.752941176470588 0.752941176470588 1"/>
      </material>
    </visual>
    <collision>
      <origin rpy="0 0 0" xyz="0 0 0"/>
      <geometry>
        <mesh filename="../meshes/camera_body_front_link.STL"/>
      </geometry>
    </collision>
  </link>
  <joint name="camera_body_front_joint" type="fixed">
    <origin rpy="-2.1468 0 -1.5708" xyz="0.090583 0.02375 0.039012"/>
    <parent link="body_yaw_link"/>
    <child link="camera_body_front_link"/>
    <axis xyz="0 0 0"/>
  </joint>
  <link name="camera_body_back_link">
    <inertial>
      <origin rpy="0 0 0" xyz="0.023316 0.000241 -0.013373"/>
      <mass value="0.1"/>
      <inertia ixx="1.5e-05" ixy="1e-06" ixz="-1e-06" iyy="0.000127" iyz="0.0" izz="0.000127"/>
    </inertial>
    <visual>
      <origin rpy="0 0 0" xyz="0 0 0"/>
      <geometry>
        <mesh filename="../meshes/camera_body_back_link.STL"/>
      </geometry>
      <material name="">
        <color rgba="0.752941176470588 0.752941176470588 0.752941176470588 1"/>
      </material>
    </visual>
    <collision>
      <origin rpy="0 0 0" xyz="0 0 0"/>
      <geometry>
        <mesh filename="../meshes/camera_body_back_link.STL"/>
      </geometry>
    </collision>
  </link>
  <joint name="camera_body_back_joint" type="fixed">
    <origin rpy="2.0071 0 -1.5708" xyz="-0.11363 0.02375 0.2746"/>
    <parent link="body_yaw_link"/>
    <child link="camera_body_back_link"/>
    <axis xyz="0 0 0"/>
  </joint>
  <link name="imu_link">
    <inertial>
      <origin rpy="0 0 0" xyz="-0.006331 -0.007725 -0.008045"/>
      <mass value="0.02"/>
      <inertia ixx="2e-06" ixy="0.0" ixz="0.0" iyy="3e-06" iyz="0.0" izz="4e-06"/>
    </inertial>
    <visual>
      <origin rpy="0 0 0" xyz="0 0 0"/>
      <geometry>
        <mesh filename="../meshes/imu_link.STL"/>
      </geometry>
      <material name="">
        <color rgba="0.752941176470588 0.752941176470588 0.752941176470588 1"/>
      </material>
    </visual>
    <collision>
      <origin rpy="0 0 0" xyz="0 0 0"/>
      <geometry>
        <mesh filename="../meshes/imu_link.STL"/>
      </geometry>
    </collision>
  </link>
  <joint name="imu_joint" type="fixed">
    <origin rpy="0 0 0" xyz="0.0499 -0.0358 -0.03194"/>
    <parent link="pelvis"/>
    <child link="imu_link"/>
    <axis xyz="0 0 0"/>
  </joint>
  <link name="L_base_link">
    <inertial>
      <origin rpy="0 0 0" xyz="0.00125804982596889 0.00181115978340497 0.069441813384378"/>
      <mass value="0.38756"/>
      <inertia ixx="0.00059831308" ixy="-5.60829e-06" ixz="-2.8701399999999997e-06" iyy="0.00050077156" iyz="-3.4830999999999997e-06" izz="0.00018467082"/>
    </inertial>
    <visual>
      <origin rpy="0 0 0" xyz="0 0 0"/>
      <geometry>
        <mesh filename="../meshes/L_base_link.STL"/>
      </geometry>
      <material name="">
        <color rgba="1 1 1 1"/>
      </material>
    </visual>
    <collision>
      <origin rpy="0 0 0" xyz="0 0 0"/>
      <geometry>
        <mesh filename="../meshes/L_base_link.STL"/>
      </geometry>
    </collision>
  </link>
  <!-- 左手拇指1：left_thumb_1 -->
  <link name="left_thumb_1">
    <inertial>
      <origin rpy="0 0 0" xyz="0.000853471678482959 -0.00482215750222577 -0.0048200002860689"/>
      <mass value="0.00483"/>
      <inertia ixx="1.9502e-07" ixy="3.536e-08" ixz="3.1e-09" iyy="1.4336e-07" iyz="7.9e-09" izz="1.6891e-07"/>
    </inertial>
    <visual>
      <origin rpy="0 0 0" xyz="0 0 0"/>
      <geometry>
        <mesh filename="../meshes/left_thumb_1.STL"/>
      </geometry>
      <material name="">
        <color rgba="1 1 1 1"/>
      </material>
    </visual>
    <collision>
      <origin rpy="0 0 0" xyz="0 0 0"/>
      <geometry>
        <mesh filename="../meshes/left_thumb_1.STL"/>
      </geometry>
    </collision>
  </link>
  <joint name="left_thumb_1_joint" type="revolute">
    <origin rpy="0 0 0" xyz="0.01696 -0.02045 0.06635"/>
    <parent link="L_base_link"/>
    <child link="left_thumb_1"/>
    <axis xyz="0 0 1"/>
    <limit effort="50" lower="0" upper="1.246165" velocity="1"/>
  </joint>
  <!-- 左手拇指2：left_thumb_2 -->
  <link name="left_thumb_2">
    <inertial>
      <origin rpy="0 0 0" xyz="-0.0194665821577184 0.0163039156062457 -0.00803846870341951"/>
      <mass value="0.05759"/>
      <inertia ixx="1.0666209999999999e-05" ixy="4.413609999999999e-06" ixz="5.150000000000001e-09" iyy="8.92353e-06" iyz="-2.59e-09" izz="1.700133e-05"/>
    </inertial>
    <visual>
      <origin rpy="0 0 0" xyz="0 0 0"/>
      <geometry>
        <mesh filename="../meshes/left_thumb_2.STL"/>
      </geometry>
      <material name="">
        <color rgba="1 1 1 1"/>
      </material>
    </visual>
    <collision>
      <origin rpy="0 0 0" xyz="0 0 0"/>
      <geometry>
        <mesh filename="../meshes/left_thumb_2.STL"/>
      </geometry>
    </collision>
  </link>
  <joint name="left_thumb_2_joint" type="revolute">
    <origin rpy="1.5708 0 1.8361" xyz="0.010735 -0.0090002 -0.0065"/>
    <parent link="left_thumb_1"/>
    <child link="left_thumb_2"/>
    <axis xyz="0 0 -1"/>
    <limit effort="50" lower="0" upper="0.48" velocity="1"/>
  </joint>
  <!-- 左手拇指3：left_thumb_3 -->
  <link name="left_thumb_3">
    <inertial>
      <origin rpy="0 0 0" xyz="-0.009466620350846 0.00207562096651074 -0.00719989129239992"/>
      <mass value="0.00985"/>
      <inertia ixx="1.21069e-06" ixy="1.0767e-07" ixz="1.0000000000000001e-11" iyy="6.011799999999999e-07" iyz="3e-11" izz="1.28966e-06"/>
    </inertial>
    <visual>
      <origin rpy="0 0 0" xyz="0 0 0"/>
      <geometry>
        <mesh filename="../meshes/left_thumb_3.STL"/>
      </geometry>
      <material name="">
        <color rgba="1 1 1 1"/>
      </material>
    </visual>
    <collision>
      <origin rpy="0 0 0" xyz="0 0 0"/>
      <geometry>
        <mesh filename="../meshes/left_thumb_3.STL"/>
      </geometry>
    </collision>
  </link>
  <joint name="left_thumb_3_joint" type="revolute">
    <origin rpy="0 0 0" xyz="-0.037617 0.041486 -0.0008"/>
    <parent link="left_thumb_2"/>
    <child link="left_thumb_3"/>
    <axis xyz="0 0 -1"/>
    <limit effort="50" lower="0" upper="0.3578" velocity="1"/>
    <mimic joint="left_thumb_2_joint" multiplier="1.1425" offset="0"/>
  </joint>
  <!-- 左手拇指4：left_thumb_4 -->
  <link name="left_thumb_4">
    <inertial>
      <origin rpy="0 0 0" xyz="-0.00604903882220686 0.00861521192699925 -0.00600331217685268"/>
      <mass value="0.00552"/>
      <inertia ixx="3.1668e-07" ixy="4.536e-08" ixz="-1.0000000000000001e-11" iyy="1.2999000000000001e-07" iyz="-4e-10" izz="3.3747e-07"/>
    </inertial>
    <visual>
      <origin rpy="0 0 0" xyz="0 0 0"/>
      <geometry>
        <mesh filename="../meshes/left_thumb_4.STL"/>
      </geometry>
      <material name="">
        <color rgba="1 1 1 1"/>
      </material>
    </visual>
    <collision>
      <origin rpy="0 0 0" xyz="0 0 0"/>
      <geometry>
        <mesh filename="../meshes/left_thumb_4.STL"/>
      </geometry>
    </collision>
  </link>
  <joint name="left_thumb_4_joint" type="revolute">
    <origin rpy="0 0 0" xyz="-0.014957 0.017012 -0.0012"/>
    <parent link="left_thumb_3"/>
    <child link="left_thumb_4"/>
    <axis xyz="0 0 -1"/>
    <limit effort="50" lower="0" upper="0.2775" velocity="1"/>
    <mimic joint="left_thumb_3_joint" multiplier="0.7508" offset="0"/>
  </joint>
  <!-- 左手食指1：left_index_1 -->
  <link name="left_index_1">
    <inertial>
      <origin rpy="0 0 0" xyz="0.0008527159848849 0.0119736084448001 0.00599989169039383"/>
      <mass value="0.01229"/>
      <inertia ixx="1.93998e-06" ixy="1.5035e-07" ixz="4.1e-10" iyy="5.6245e-07" iyz="3.49e-09" izz="2.05872e-06"/>
    </inertial>
    <visual>
      <origin rpy="0 0 0" xyz="0 0 0"/>
      <geometry>
        <mesh filename="../meshes/left_index_1.STL"/>
      </geometry>
      <material name="">
        <color rgba="1 1 1 1"/>
      </material>
    </visual>
    <collision>
      <origin rpy="0 0 0" xyz="0 0 0"/>
      <geometry>
        <mesh filename="../meshes/left_index_1.STL"/>
      </geometry>
    </collision>
  </link>
  <joint name="left_index_1_joint" type="revolute">
    <origin rpy="1.6057 0 0" xyz="-0.00028533 -0.020275 0.13695"/>
    <parent link="L_base_link"/>
    <child link="left_index_1"/>
    <axis xyz="0 0 -1"/>
    <limit effort="50" lower="0" upper="1.333" velocity="1"/>
  </joint>
  <!-- 左手食指2：left_index_2 -->
  <link name="left_index_2">
    <inertial>
      <origin rpy="0 0 0" xyz="0.00408344708691732 0.0192601764486991 0.00500003100756935"/>
      <mass value="0.00633"/>
      <inertia ixx="9.4327e-07" ixy="3.8912e-07" ixz="2.0000000000000002e-11" iyy="2.897e-07" iyz="5e-11" izz="1.14024e-06"/>
    </inertial>
    <visual>
      <origin rpy="0 0 0" xyz="0 0 0"/>
      <geometry>
        <mesh filename="../meshes/left_index_2.STL"/>
      </geometry>
      <material name="">
        <color rgba="1 1 1 1"/>
      </material>
    </visual>
    <collision>
      <origin rpy="0 0 0" xyz="0 0 0"/>
      <geometry>
        <mesh filename="../meshes/left_index_2.STL"/>
      </geometry>
    </collision>
  </link>
  <joint name="left_index_2_joint" type="revolute">
    <origin rpy="0 0 0" xyz="0.0080993 0.031095 0.001"/>
    <parent link="left_index_1"/>
    <child link="left_index_2"/>
    <axis xyz="0 0 -1"/>
    <limit effort="50" lower="0" upper="1.527" velocity="1"/>
    <mimic joint="left_index_1_joint" multiplier="1.1169" offset="0"/>
  </joint>
  <!-- 左手中指1：left_middle_1 -->
  <link name="left_middle_1">
    <inertial>
      <origin rpy="0 0 0" xyz="0.00085287755691596 0.0119736405947354 0.00599988891959347"/>
      <mass value="0.01229"/>
      <inertia ixx="1.94e-06" ixy="1.5036e-07" ixz="9.899999999999999e-10" iyy="5.6248e-07" iyz="5.01e-09" izz="2.05872e-06"/>
    </inertial>
    <visual>
      <origin rpy="0 0 0" xyz="0 0 0"/>
      <geometry>
        <mesh filename="../meshes/left_middle_1.STL"/>
      </geometry>
      <material name="">
        <color rgba="1 1 1 1"/>
      </material>
    </visual>
    <collision>
      <origin rpy="0 0 0" xyz="0 0 0"/>
      <geometry>
        <mesh filename="../meshes/left_middle_1.STL"/>
      </geometry>
    </collision>
  </link>
  <joint name="left_middle_1_joint" type="revolute">
    <origin rpy="1.5708 0 0" xyz="-0.00028533 -0.00095 0.1371"/>
    <parent link="L_base_link"/>
    <child link="left_middle_1"/>
    <axis xyz="0 0 -1"/>
    <limit effort="50" lower="0" upper="1.333" velocity="1"/>
  </joint>
  <!-- 左手中指2：left_middle_2 -->
  <link name="left_middle_2">
    <inertial>
      <origin rpy="0 0 0" xyz="0.00471131608223271 0.0203464425452461 0.00500013550498847"/>
      <mass value="0.00681"/>
      <inertia ixx="1.18348e-06" ixy="5.0397e-07" ixz="0.0" iyy="3.558e-07" iyz="0.0" izz="1.43878e-06"/>
    </inertial>
    <visual>
      <origin rpy="0 0 0" xyz="0 0 0"/>
      <geometry>
        <mesh filename="../meshes/left_middle_2.STL"/>
      </geometry>
      <material name="">
        <color rgba="1 1 1 1"/>
      </material>
    </visual>
    <collision>
      <origin rpy="0 0 0" xyz="0 0 0"/>
      <geometry>
        <mesh filename="../meshes/left_middle_2.STL"/>
      </geometry>
    </collision>
  </link>
  <joint name="left_middle_2_joint" type="revolute">
    <origin rpy="0 0 0" xyz="0.0080996 0.031095 0.001"/>
    <parent link="left_middle_1"/>
    <child link="left_middle_2"/>
    <axis xyz="0 0 -1"/>
    <limit effort="50" lower="0" upper="1.527" velocity="1"/>
    <mimic joint="left_middle_1_joint" multiplier="1.1169" offset="0"/>
  </joint>
  <!-- 左手无名指1：left_ring_1 -->
  <link name="left_ring_1">
    <inertial>
      <origin rpy="0 0 0" xyz="0.000852611292407851 0.0119736634067538 0.00599988335942421"/>
      <mass value="0.01229"/>
      <inertia ixx="1.93998e-06" ixy="1.5033e-07" ixz="5.1e-10" iyy="5.6244e-07" iyz="3.52e-09" izz="2.05872e-06"/>
    </inertial>
    <visual>
      <origin rpy="0 0 0" xyz="0 0 0"/>
      <geometry>
        <mesh filename="../meshes/left_ring_1.STL"/>
      </geometry>
      <material name="">
        <color rgba="1 1 1 1"/>
      </material>
    </visual>
    <collision>
      <origin rpy="0 0 0" xyz="0 0 0"/>
      <geometry>
        <mesh filename="../meshes/left_ring_1.STL"/>
      </geometry>
    </collision>
  </link>
  <joint name="left_ring_1_joint" type="revolute">
    <origin rpy="1.5184 0 0" xyz="-0.00028533 0.018271 0.13628"/>
    <parent link="L_base_link"/>
    <child link="left_ring_1"/>
    <axis xyz="0 0 -1"/>
    <limit effort="50" lower="0" upper="1.333" velocity="1"/>
  </joint>
  <!-- 左手无名指2：left_ring_2 -->
  <link name="left_ring_2">
    <inertial>
      <origin rpy="0 0 0" xyz="0.00408299506259779 0.0192602956948013 0.00500000332159135"/>
      <mass value="0.00633"/>
      <inertia ixx="6.4877680e-07" ixy="-2.6414408e-07" ixz="-8.90807474e-013" iyy="2.084188844e-07" iyz="-1.3837101e-12" izz="7.8180149e-07"/>
    </inertial>
    <visual>
      <origin rpy="0 0 0" xyz="0 0 0"/>
      <geometry>
        <mesh filename="../meshes/left_ring_2.STL"/>
      </geometry>
      <material name="">
        <color rgba="1 1 1 1"/>
      </material>
    </visual>
    <collision>
      <origin rpy="0 0 0" xyz="0 0 0"/>
      <geometry>
        <mesh filename="../meshes/left_ring_2.STL"/>
      </geometry>
    </collision>
  </link>
  <joint name="left_ring_2_joint" type="revolute">
    <origin rpy="0 0 0" xyz="0.0080989 0.031095 0.001"/>
    <parent link="left_ring_1"/>
    <child link="left_ring_2"/>
    <axis xyz="0 0 -1"/>
    <limit effort="50" lower="0" upper="1.527" velocity="1"/>
    <mimic joint="left_ring_1_joint" multiplier="1.1169" offset="0"/>
  </joint>
  <!-- 左手小指1：left_little_1 -->
  <link name="left_little_1">
    <inertial>
      <origin rpy="0 0 0" xyz="0.000851752984712406 0.0119737230065286 0.00599988919520877"/>
      <mass value="0.01229"/>
      <inertia ixx="1.94e-06" ixy="1.5023e-07" ixz="3e-10" iyy="5.6242e-07" iyz="3.18e-09" izz="2.05872e-06"/>
    </inertial>
    <visual>
      <origin rpy="0 0 0" xyz="0 0 0"/>
      <geometry>
        <mesh filename="../meshes/left_little_1.STL"/>
      </geometry>
      <material name="">
        <color rgba="1 1 1 1"/>
      </material>
    </visual>
    <collision>
      <origin rpy="0 0 0" xyz="0 0 0"/>
      <geometry>
        <mesh filename="../meshes/left_little_1.STL"/>
      </geometry>
    </collision>
  </link>
  <joint name="left_little_1_joint" type="revolute">
    <origin rpy="1.4661 0 0" xyz="-0.00028533 0.037422 0.13446"/>
    <parent link="L_base_link"/>
    <child link="left_little_1"/>
    <axis xyz="0 0 -1"/>
    <limit effort="50" lower="0" upper="1.333" velocity="1"/>
  </joint>
  <!-- 左手小指2：left_little_2 -->
  <link name="left_little_2">
    <inertial>
      <origin rpy="0 0 0" xyz="0.00273890807896854 0.0161632709360688 0.00500586036971424"/>
      <mass value="0.00525"/>
      <inertia ixx="5.5787e-07" ixy="2.175e-07" ixz="0.0" iyy="1.8624e-07" iyz="0.0" izz="6.6906e-07"/>
    </inertial>
    <visual>
      <origin rpy="0 0 0" xyz="0 0 0"/>
      <geometry>
        <mesh filename="../meshes/left_little_2.STL"/>
      </geometry>
      <material name="">
        <color rgba="1 1 1 1"/>
      </material>
    </visual>
    <collision>
      <origin rpy="0 0 0" xyz="0 0 0"/>
      <geometry>
        <mesh filename="../meshes/left_little_2.STL"/>
      </geometry>
    </collision>
  </link>
  <joint name="left_little_2_joint" type="revolute">
    <origin rpy="0 0 0" xyz="0.0080966 0.031096 0.001"/>
    <parent link="left_little_1"/>
    <child link="left_little_2"/>
    <axis xyz="0 0 -1"/>
    <limit effort="50" lower="0" upper="1.527" velocity="1"/>
    <mimic joint="left_little_1_joint" multiplier="1.1169" offset="0"/>
  </joint>
  <!-- 左手与主体的固定关节：连接L_base_link到left_tcp_link -->
  <joint name="left_hand_to_tcp" type="fixed">
    <origin rpy="3.14 0 0" xyz="0 0 0"/>
    <parent link="left_tcp_link"/>
    <child link="L_base_link"/>
  </joint>
  <!-- 右手根链接：R_base_link -->
  <link name="R_base_link">
    <inertial>
      <origin rpy="0 0 0" xyz="0.00252515168164585 -0.001960054926157 0.0660467739648412"/>
      <mass value="0.38756"/>
      <inertia ixx="0.00059831308" ixy="5.60829e-06" ixz="2.8701399999999997e-06" iyy="0.00050077156" iyz="3.4830999999999997e-06" izz="0.00018467082"/>
    </inertial>
    <visual>
      <origin rpy="0 0 0" xyz="0 0 0"/>
      <geometry>
        <mesh filename="../meshes/R_base_link.STL"/>
      </geometry>
      <material name="">
        <color rgba="1 1 1 1"/>
      </material>
    </visual>
    <collision>
      <origin rpy="0 0 0" xyz="0 0 0"/>
      <geometry>
        <mesh filename="../meshes/R_base_link.STL"/>
      </geometry>
    </collision>
  </link>
  <!-- 右手拇指1：right_thumb_1 -->
  <link name="right_thumb_1">
    <inertial>
      <origin rpy="0 0 0" xyz="0.000853491366153925 0.00482216769884483 -0.00481999614705116"/>
      <mass value="0.00483"/>
      <inertia ixx="1.9502e-07" ixy="-3.536e-08" ixz="-3.1e-09" iyy="1.4336e-07" iyz="-7.9e-09" izz="1.6891e-07"/>
    </inertial>
    <visual>
      <origin rpy="0 0 0" xyz="0 0 0"/>
      <geometry>
        <mesh filename="../meshes/right_thumb_1.STL"/>
      </geometry>
      <material name="">
        <color rgba="1 1 1 1"/>
      </material>
    </visual>
    <collision>
      <origin rpy="0 0 0" xyz="0 0 0"/>
      <geometry>
        <mesh filename="../meshes/right_thumb_1.STL"/>
      </geometry>
    </collision>
  </link>
  <joint name="right_thumb_1_joint" type="revolute">
    <origin rpy="0 0 0" xyz="0.01696 0.02045 0.06635"/>
    <parent link="R_base_link"/>
    <child link="right_thumb_1"/>
    <axis xyz="0 0 -1"/>
    <limit effort="50" lower="0" upper="1.246165" velocity="1"/>
  </joint>
  <!-- 右手拇指2：right_thumb_2 -->
  <link name="right_thumb_2">
    <inertial>
      <origin rpy="0 0 0" xyz="0.0194641293930403 0.0162980383727088 -0.00803857337744943"/>
      <mass value="0.05759"/>
      <inertia ixx="1.06662e-05" ixy="-4.4136e-06" ixz="-5.15e-09" iyy="8.92353e-06" iyz="2.59e-09" izz="1.700133e-05"/>
    </inertial>
    <visual>
      <origin rpy="0 0 0" xyz="0 0 0"/>
      <geometry>
        <mesh filename="../meshes/right_thumb_2.STL"/>
      </geometry>
      <material name="">
        <color rgba="1 1 1 1"/>
      </material>
    </visual>
    <collision>
      <origin rpy="0 0 0" xyz="0 0 0"/>
      <geometry>
        <mesh filename="../meshes/right_thumb_2.STL"/>
      </geometry>
    </collision>
  </link>
  <joint name="right_thumb_2_joint" type="revolute">
    <origin rpy="1.5708 0 1.3055" xyz="0.010735 0.0090002 -0.0065"/>
    <parent link="right_thumb_1"/>
    <child link="right_thumb_2"/>
    <axis xyz="0 0 1"/>
    <limit effort="50" lower="0" upper="0.48" velocity="1"/>
  </joint>
  <link name="right_thumb_3">
    <inertial>
      <origin rpy="0 0 0" xyz="0.00946651884646355 0.00207630823866701 -0.00720000588824668"/>
      <mass value="0.00985"/>
      <inertia ixx="1.21069e-06" ixy="-1.0767e-07" ixz="-1e-11" iyy="6.0118e-07" iyz="-3e-11" izz="1.28966e-06"/>
    </inertial>
    <visual>
      <origin rpy="0 0 0" xyz="0 0 0"/>
      <geometry>
        <mesh filename="../meshes/right_thumb_3.STL"/>
      </geometry>
      <material name="">
        <color rgba="1 1 1 1"/>
      </material>
    </visual>
    <collision>
      <origin rpy="0 0 0" xyz="0 0 0"/>
      <geometry>
        <mesh filename="../meshes/right_thumb_3.STL"/>
      </geometry>
    </collision>
  </link>
  <joint name="right_thumb_3_joint" type="revolute">
    <origin rpy="0 0 0" xyz="0.037617 0.041486 -0.0008"/>
    <parent link="right_thumb_2"/>
    <child link="right_thumb_3"/>
    <axis xyz="0 0 1"/>
    <limit effort="50" lower="0" upper="0.3578" velocity="1"/>
    <mimic joint="right_thumb_2_joint" multiplier="1.1425" offset="0"/>
  </joint>
  <!-- 右手拇指4：right_thumb_4 -->
  <link name="right_thumb_4">
    <inertial>
      <origin rpy="0 0 0" xyz="0.00604904909827651 0.00861522746372045 -0.00600329390500667"/>
      <mass value="0.00552"/>
      <inertia ixx="3.1668e-07" ixy="-4.536e-08" ixz="1e-11" iyy="1.2999e-07" iyz="4e-10" izz="3.3747e-07"/>
    </inertial>
    <visual>
      <origin rpy="0 0 0" xyz="0 0 0"/>
      <geometry>
        <mesh filename="../meshes/right_thumb_4.STL"/>
      </geometry>
      <material name="">
        <color rgba="1 1 1 1"/>
      </material>
    </visual>
    <collision>
      <origin rpy="0 0 0" xyz="0 0 0"/>
      <geometry>
        <mesh filename="../meshes/right_thumb_4.STL"/>
      </geometry>
    </collision>
  </link>
  <joint name="right_thumb_4_joint" type="revolute">
    <origin rpy="0 0 0" xyz="0.014957 0.017012 -0.0012"/>
    <parent link="right_thumb_3"/>
    <child link="right_thumb_4"/>
    <axis xyz="0 0 1"/>
    <limit effort="50" lower="0" upper="0.2775" velocity="1"/>
    <mimic joint="right_thumb_3_joint" multiplier="0.7508" offset="0"/>
  </joint>
  <!-- 右手食指1：right_index_1 -->
  <link name="right_index_1">
    <inertial>
      <origin rpy="0 0 0" xyz="0.000852715296526529 0.0119735955318245 -0.00599986563267159"/>
      <mass value="0.01229"/>
      <inertia ixx="1.93998e-06" ixy="-1.5035e-07" ixz="-4.1e-10" iyy="5.6245e-07" iyz="-3.49e-09" izz="2.05872e-06"/>
    </inertial>
    <visual>
      <origin rpy="0 0 0" xyz="0 0 0"/>
      <geometry>
        <mesh filename="../meshes/right_index_1.STL"/>
      </geometry>
      <material name="">
        <color rgba="1 1 1 1"/>
      </material>
    </visual>
    <collision>
      <origin rpy="0 0 0" xyz="0 0 0"/>
      <geometry>
        <mesh filename="../meshes/right_index_1.STL"/>
      </geometry>
    </collision>
  </link>
  <joint name="right_index_1_joint" type="revolute">
    <origin rpy="1.5359 0 0" xyz="-0.000285 0.020275 0.136946"/>
    <parent link="R_base_link"/>
    <child link="right_index_1"/>
    <axis xyz="0 -0.069756  -0.997564"/>
    <limit effort="50" lower="0" upper="1.333" velocity="1"/>
  </joint>
  <!-- 右手食指2：right_index_2 -->
  <link name="right_index_2">
    <inertial>
      <origin rpy="0 0 0" xyz="0.00408342999190195 0.0192600939391442 -0.00500000380847467"/>
      <mass value="0.00633"/>
      <inertia ixx="9.4327e-07" ixy="-3.8912e-07" ixz="-2e-11" iyy="2.897e-07" iyz="-5e-11" izz="1.14024e-06"/>
    </inertial>
    <visual>
      <origin rpy="0 0 0" xyz="0 0 0"/>
      <geometry>
        <mesh filename="../meshes/right_index_2.STL"/>
      </geometry>
      <material name="">
        <color rgba="1 1 1 1"/>
      </material>
    </visual>
    <collision>
      <origin rpy="0 0 0" xyz="0 0 0"/>
      <geometry>
        <mesh filename="../meshes/right_index_2.STL"/>
      </geometry>
    </collision>
  </link>
  <joint name="right_index_2_joint" type="revolute">
    <origin rpy="0 0 0" xyz="0.008099 0.031095 -0.001"/>
    <parent link="right_index_1"/>
    <child link="right_index_2"/>
    <axis xyz="0 0 -1"/>
    <limit effort="50" lower="0" upper="1.527" velocity="1"/>
    <mimic joint="right_index_1_joint" multiplier="1.1169" offset="0"/>
  </joint>
  <!-- 右手中指1：right_middle_1 -->
  <link name="right_middle_1">
    <inertial>
      <origin rpy="0 0 0" xyz="0.000852855866232599 0.011973606798452 -0.00399984588006246"/>
      <mass value="0.01229"/>
      <inertia ixx="1.94e-06" ixy="-1.5036e-07" ixz="-9.9e-10" iyy="5.6248e-07" iyz="-5.01e-09" izz="2.05872e-06"/>
    </inertial>
    <visual>
      <origin rpy="0 0 0" xyz="0 0 0"/>
      <geometry>
        <mesh filename="../meshes/right_middle_1.STL"/>
      </geometry>
      <material name="">
        <color rgba="1 1 1 1"/>
      </material>
    </visual>
    <collision>
      <origin rpy="0 0 0" xyz="0 0 0"/>
      <geometry>
        <mesh filename="../meshes/right_middle_1.STL"/>
      </geometry>
    </collision>
  </link>
  <joint name="right_middle_1_joint" type="revolute">
    <origin rpy="1.5708 0 0" xyz="-0.000285 0.00295 0.1371"/>
    <parent link="R_base_link"/>
    <child link="right_middle_1"/>
    <axis xyz="0 0 -1"/>
    <limit effort="50" lower="0" upper="1.333" velocity="1"/>
  </joint>
  <!-- 右手中指2：right_middle_2 -->
  <link name="right_middle_2">
    <inertial>
      <origin rpy="0 0 0" xyz="0.0047113458880482 0.0203465768773643 -0.00500003269708214"/>
      <mass value="0.00681"/>
      <inertia ixx="1.18348e-06" ixy="-5.0397e-07" ixz="0.0" iyy="3.558e-07" iyz="0.0" izz="1.43878e-06"/>
    </inertial>
    <visual>
      <origin rpy="0 0 0" xyz="0 0 0"/>
      <geometry>
        <mesh filename="../meshes/right_middle_2.STL"/>
      </geometry>
      <material name="">
        <color rgba="1 1 1 1"/>
      </material>
    </visual>
    <collision>
      <origin rpy="0 0 0" xyz="0 0 0"/>
      <geometry>
        <mesh filename="../meshes/right_middle_2.STL"/>
      </geometry>
    </collision>
  </link>
  <joint name="right_middle_2_joint" type="revolute">
    <origin rpy="0 0 0" xyz="0.0081 0.031095 0.001"/>
    <parent link="right_middle_1"/>
    <child link="right_middle_2"/>
    <axis xyz="0 0 -1"/>
    <limit effort="50" lower="0" upper="1.527" velocity="1"/>
    <mimic joint="right_middle_1_joint" multiplier="1.1169" offset="0"/>
  </joint>
  <!-- 右手无名指1：right_ring_1 -->
  <link name="right_ring_1">
    <inertial>
      <origin rpy="0 0 0" xyz="0.00085245845917839 0.0119734648811593 -0.00599989251266642"/>
      <mass value="0.01229"/>
      <inertia ixx="1.93998e-06" ixy="-1.5033e-07" ixz="-5.1e-10" iyy="5.6244e-07" iyz="-3.52e-09" izz="2.05872e-06"/>
    </inertial>
    <visual>
      <origin rpy="0 0 0" xyz="0 0 0"/>
      <geometry>
        <mesh filename="../meshes/right_ring_1.STL"/>
      </geometry>
      <material name="">
        <color rgba="1 1 1 1"/>
      </material>
    </visual>
    <collision>
      <origin rpy="0 0 0" xyz="0 0 0"/>
      <geometry>
        <mesh filename="../meshes/right_ring_1.STL"/>
      </geometry>
    </collision>
  </link>
  <joint name="right_ring_1_joint" type="revolute">
    <origin rpy="1.6232 0 0" xyz="-0.000285 -0.018271 0.136282"/>
    <parent link="R_base_link"/>
    <child link="right_ring_1"/>
    <axis xyz="0 0 -1"/>
    <limit effort="50" lower="0" upper="1.333" velocity="1"/>
  </joint>
  <!-- 右手无名指2：right_ring_2 -->
  <link name="right_ring_2">
    <inertial>
      <origin rpy="0 0 0" xyz="0.00408287363348225 0.0192599767415159 -0.00499998343104271"/>
      <mass value="0.00633"/>
      <inertia ixx="9.4329e-07" ixy="-3.8762e-07" ixz="-3.394e-08" iyy="2.9615e-07" iyz="-7.389e-08" izz="1.13377e-06"/>
    </inertial>
    <visual>
      <origin rpy="0 0 0" xyz="0 0 0"/>
      <geometry>
        <mesh filename="../meshes/right_ring_2.STL"/>
      </geometry>
      <material name="">
        <color rgba="1 1 1 1"/>
      </material>
    </visual>
    <collision>
      <origin rpy="0 0 0" xyz="0 0 0"/>
      <geometry>
        <mesh filename="../meshes/right_ring_2.STL"/>
      </geometry>
    </collision>
  </link>
  <joint name="right_ring_2_joint" type="revolute">
    <origin rpy="0 0 0" xyz="0.008099 0.031095 -0.001"/>
    <parent link="right_ring_1"/>
    <child link="right_ring_2"/>
    <axis xyz="0 0 -1"/>
    <limit effort="50" lower="0" upper="1.527" velocity="1"/>
    <mimic joint="right_ring_1_joint" multiplier="1.1169" offset="0"/>
  </joint>
  <!-- 右手小指1：right_little_1 -->
  <link name="right_little_1">
    <inertial>
      <origin rpy="0 0 0" xyz="0.000851610973032574 0.0119735303202265 -0.00599989467442243"/>
      <mass value="0.01229"/>
      <inertia ixx="1.94e-06" ixy="-1.5023e-07" ixz="-3e-10" iyy="5.6242e-07" iyz="-3.18e-09" izz="2.05872e-06"/>
    </inertial>
    <visual>
      <origin rpy="0 0 0" xyz="0 0 0"/>
      <geometry>
        <mesh filename="../meshes/right_little_1.STL"/>
      </geometry>
      <material name="">
        <color rgba="1 1 1 1"/>
      </material>
    </visual>
    <collision>
      <origin rpy="0 0 0" xyz="0 0 0"/>
      <geometry>
        <mesh filename="../meshes/right_little_1.STL"/>
      </geometry>
    </collision>
  </link>
  <joint name="right_little_1_joint" type="revolute">
    <origin rpy="1.6755 0 0" xyz="-0.000285 -0.037422 0.13446"/>
    <parent link="R_base_link"/>
    <child link="right_little_1"/>
    <axis xyz="0 0 -1"/>
    <limit effort="50" lower="0" upper="1.333" velocity="1"/>
  </joint>
  <!-- 右手小指2：right_little_2 -->
  <link name="right_little_2">
    <inertial>
      <origin rpy="0 0 0" xyz="0.00273929963119374 0.0161600317264199 -0.00499667765900381"/>
      <mass value="0.00525"/>
      <inertia ixx="5.5787e-07" ixy="-2.175e-07" ixz="0.0" iyy="1.8624e-07" iyz="0.0" izz="6.6906e-07"/>
    </inertial>
    <visual>
      <origin rpy="0 0 0" xyz="0 0 0"/>
      <geometry>
        <mesh filename="../meshes/right_little_2.STL"/>
      </geometry>
      <material name="">
        <color rgba="1 1 1 1"/>
      </material>
    </visual>
    <collision>
      <origin rpy="0 0 0" xyz="0 0 0"/>
      <geometry>
        <mesh filename="../meshes/right_little_2.STL"/>
      </geometry>
    </collision>
  </link>
  <joint name="right_little_2_joint" type="revolute">
    <origin rpy="0 0 0" xyz="0.008097 0.031096 -0.001"/>
    <parent link="right_little_1"/>
    <child link="right_little_2"/>
    <axis xyz="0 0 -1"/>
    <limit effort="50" lower="0" upper="1.527" velocity="1"/>
    <mimic joint="right_little_1_joint" multiplier="1.1169" offset="0"/>
  </joint>
  <joint name="right_hand_to_tcp" type="fixed">
    <origin rpy="3.14 0 0" xyz="0 0 0"/>
    <parent link="right_tcp_link"/>
    <child link="R_base_link"/>
  </joint>
</robot>
